<mujoco model="two_robot_scene">
  <compiler angle="radian" coordinate="local"/>
  <option timestep="0.01"/>

  <size njmax="1000" nconmax="200"/>

  <visual>
    <map znear="0.01"/>
  </visual>

  <!-- World body -->
  <worldbody>
    <!-- Ground -->
    <geom name="floor" type="plane" size="5 5 0.1" rgba="0.8 0.9 0.8 1"/>

    <!-- Platform -->
    <body name="platform" pos="0.5 0 0.1">
      <geom type="box" size="0.2 0.2 0.05" rgba="0.3 0.3 0.8 1"/>
    </body>

    <!-- Object -->
    <body name="object" pos="0 0 0.05">
      <joint name="object_free" type="free"/>
      <geom type="box" size="0.03 0.03 0.03" rgba="1 0 0 1"/>
    </body>

    <!-- Robot A -->
    <body name="robotA_base" pos="-0.4 0 0">
      <geom type="cylinder" size="0.05 0.01" rgba="0 0 1 1"/>
      <joint name="robotA_joint1" type="hinge" axis="0 0 1"/>
      <body name="robotA_link1" pos="0 0 0.1">
        <geom type="capsule" fromto="0 0 0 0.2 0 0" size="0.02" rgba="0 0 1 1"/>
        <joint name="robotA_joint2" type="hinge" axis="0 1 0"/>
        <body name="robotA_gripper" pos="0.2 0 0">
          <geom type="sphere" size="0.03" rgba="0 1 0 1"/>
        </body>
      </body>
    </body>

    <!-- Robot B -->
    <body name="robotB_base" pos="1 0 0">
      <geom type="cylinder" size="0.05 0.01" rgba="1 0 0 1"/>
      <joint name="robotB_joint1" type="hinge" axis="0 0 1"/>
      <body name="robotB_link1" pos="0 0 0.1">
        <geom type="capsule" fromto="0 0 0 -0.2 0 0" size="0.02" rgba="1 0 0 1"/>
        <joint name="robotB_joint2" type="hinge" axis="0 1 0"/>
        <body name="robotB_gripper" pos="-0.2 0 0">
          <geom type="sphere" size="0.03" rgba="1 1 0 1"/>
        </body>
      </body>
    </body>
  </worldbody>

  <actuator>
    <!-- Robot A -->
    <motor joint="robotA_joint1" ctrlrange="-3.14 3.14"/>
    <motor joint="robotA_joint2" ctrlrange="-1.57 1.57"/>

    <!-- Robot B -->
    <motor joint="robotB_joint1" ctrlrange="-3.14 3.14"/>
    <motor joint="robotB_joint2" ctrlrange="-1.57 1.57"/>
  </actuator>
</mujoco>
